some_global = 1337

def test_raise_python_exception() -> str:
    a = 1
    b = 2
    raise ValueError("This is a Python exception")
